<?xml version="1.0"?>
<robot xmlns:xacro="http://www.ros.org/wiki/xacro">

    <material name="blue"> <color rgba="0 0 0.8 1"/></material>
    <material name="green"><color rgba="0 1 0 1"/></material>
    <material name="orange"><color rgba="1 0.5 0 1"/></material>
    <material name="black"><color rgba="0 0 0 1"/></material>

    <xacro:macro name="cylinder_inertia" params="m r h">
        <inertial>
        <mass value="${m}"/>
        <inertia ixx="${(m/12) * (3*r*r + h*h)}" ixy="0" ixz="0"
                iyy="${(m/12) * (3*r*r + h*h)}" iyz="0"
                izz="${(m/2) * (r*r)}"/>
        </inertial>
    </xacro:macro>

    <xacro:macro name="wheel" params="prefix x_reflect y_reflect">
        <link name="${prefix}_wheel">
        <visual>
            <origin xyz="0 0 0" rpy="${pi/2} 0 0"/>
            <geometry>
                <cylinder radius="${wheel_radius}" length="${wheel_width}"/>
                <!-- <sphere radius="${wheel_radius}"/> -->
            </geometry>
            <material name="orange"/>
        </visual>
        <collision>
            <origin xyz="0 0 0" rpy="${pi/2} 0 0"/>
            <geometry>
                <!-- <cylinder radius="${wheel_radius}" length="0.01"/> -->
                <sphere radius="${wheel_radius}"/>
            </geometry>
        </collision>
        <xacro:cylinder_inertia m="${wheel_mass}" r="${wheel_radius}" h="${wheel_width}"/>
        </link>

        <joint name="${prefix}_wheel_joint" type="continuous">
        <parent link="base_link"/>
        <child link="${prefix}_wheel"/>
        <origin xyz="${x_reflect*wheel_x_offset} ${y_reflect*wheel_y_offset} ${wheel_z_offset}" rpy="0 0 0"/>
        <axis xyz="0 1 0"/>
        </joint>

        <gazebo reference="${prefix}_wheel">
            <material>Gazebo/Blue</material>
            <mu1 value="0.2"/>
            <mu2 value="0.2"/>
            <fdir1 value="1 0 0"/>
            <kp value="10000000.0" />
            <kd value="1.0" />
        </gazebo>
    </xacro:macro>

    <link name="base_footprint"/>

    <joint name="base_joint" type="fixed">
        <parent link="base_footprint"/>
        <child link="base_link"/>
        <origin xyz="0 0 ${3*wheel_radius}" rpy="0 0 0"/>
    </joint>

    <link name="base_link">
        <visual>
        <geometry>
            <box size="${chassis_length} ${chassis_width} ${chassis_height}"/>
        </geometry>
        <material name="green"/>
        </visual>
        <collision>
        <geometry>
            <box size="${chassis_length} ${chassis_width} ${chassis_height}"/>
        </geometry>
        </collision>
        <inertial>
        <mass value="${chassis_mass}"/>
        <inertia ixx="${(chassis_mass/12) * (chassis_width**2 + chassis_height**2)}" ixy="0" ixz="0"
                iyy="${(chassis_mass/12) * (chassis_length**2 + chassis_height**2)}" iyz="0"
                izz="${(chassis_mass/12) * (chassis_length**2 + chassis_width**2)}"/>
        </inertial>
    </link>
    <gazebo reference="base_link">
        <material>Gazebo/Blue</material>
    </gazebo>

    <!-- Aruco marker -->
    <!-- <link name="robot_picture">
        <visual>
            <geometry>
                <box size="0.3 0.3 0.01"/>
            </geometry>
        </visual>
    </link>

    <gazebo reference="robot_picture">
        <material>MyRobot/MyTexture</material>
    </gazebo>
    <joint name="robot_picture_joint" type="fixed">
        <parent link="base_link"/>
        <child link="robot_picture"/>
        <origin xyz="0 0 ${chassis_height/2}" rpy="0 0 0"/>
    </joint> -->

    <xacro:wheel prefix="front_left"  x_reflect="1"  y_reflect="1"/>
    <xacro:wheel prefix="front_right" x_reflect="1"  y_reflect="-1"/>
    <xacro:wheel prefix="rear_left"   x_reflect="-1" y_reflect="1"/>
    <xacro:wheel prefix="rear_right"  x_reflect="-1" y_reflect="-1"/>

</robot>